Workbook

Sheet 浙大
A1: 科目 | B1: 预算批复数 | D1: 预算执行数 | F1: 执行率 | H1: 结余数
B2: 中央财政资金 | C2: 其他来源资金 | D2: 中央财政资金 | E2: 其他来源资金 | F2: 中央财政资金 | G2: 其他来源资金 | H2: 中央财政资金 | I2: 其他来源资金
A3: 一、课题支出合计 | B3: =B4+B29 -> 88 | C3: =C4+C29 -> 176 | D3: =D4+D29 -> 54.920605 | E3: =E4+E29 -> 45.319165 | F3: =D3/B3 -> 0.62409778 | G3: =E3/C3 -> 0.25749526 | H3: =B3-D3 -> 33.079395 | I3: =C3-E3 -> 130.68084
A4: （一）直接费用 | B4: 68 | C4: 176 | D4: =D5+D11+D12+D13+D14+D25+D26+D27+D28 -> 41.632605 | E4: =E5+E11+E12+E13+E14+E25+E26+E27+E28 -> 45.319165 | F4: =D4/B4 -> 0.61224419 | G4: =E4/C4 -> 0.25749526 | H4: =B4-D4 -> 26.367395 | I4: =C4-E4 -> 130.68084
A5: 1.设备费 | B5: 0 | C5: 0 | D5: 0 | E5: 0 | F5: 0 | G5: =E5/C5 -> #DIV/0! | H5: =B5-D5 -> 0 | I5: =C5-E5 -> 0
A6: （1）购置设备费 | B6: 0 | C6: 0 | D6: 0 | E6: 0 | F6: 0 | G6: =E6/C6 -> #DIV/0! | H6: =B6-D6 -> 0 | I6: =C6-E6 -> 0
A7: （2）试制设备费 | B7: 0 | C7: 0 | D7: 0 | E7: 0 | F7: 0 | G7: =E7/C7 -> #DIV/0! | H7: =B7-D7 -> 0 | I7: =C7-E7 -> 0
A8: （3）设备改造与租赁费 | B8: 0 | C8: 0 | D8: 0 | E8: 0 | F8: 0 | G8: =E8/C8 -> #DIV/0! | H8: =B8-D8 -> 0 | I8: =C8-E8 -> 0
A9: 1）设备改造费 | B9: 0 | C9: 0 | D9: 0 | E9: 0 | F9: 0 | G9: =E9/C9 -> #DIV/0! | H9: =B9-D9 -> 0 | I9: =C9-E9 -> 0
A10: 2）设备租赁费 | B10: 0 | C10: 0 | D10: 0 | E10: 0 | F10: 0 | G10: =E10/C10 -> #DIV/0! | H10: =B10-D10 -> 0 | I10: =C10-E10 -> 0
A11: 2.材料费 | B11: 23.8 | C11: 80 | D11: 10.306775 | E11: 44.6 | F11: =D11/B11 -> 0.43305777 | G11: =E11/C11 -> 0.5575 | H11: =B11-D11 -> 13.493225 | I11: =C11-E11 -> 35.4
A12: 3.测试化验加工费 | B12: 14 | C12: 56 | D12: 0.011 | E12: 0 | F12: =D12/B12 -> 0.00078571429 | G12: =E12/C12 -> 0 | H12: =B12-D12 -> 13.989 | I12: =C12-E12 -> 56
A13: 4.燃料动力费 | B13: 0 | C13: 0 | D13: 0 | E13: 0 | F13: 0 | G13: =E13/C13 -> #DIV/0! | H13: =B13-D13 -> 0 | I13: =C13-E13 -> 0
A14: 5.会议/差旅/国际合作交流费 | B14: 8 | C14: 0 | D14: 7.252751 | E14: 0.719165 | F14: =D14/B14 -> 0.90659387 | G14: =E14/C14 -> #DIV/0! | H14: =B14-D14 -> 0.747249 | I14: =C14-E14 -> -0.719165
A25: 6.出版/文献/信息传播/知识产权事务费 | B25: 6 | C25: 0 | D25: 1.912079 | E25: 0 | F25: =D25/B25 -> 0.31867983 | G25: =E25/C25 -> #DIV/0! | H25: =B25-D25 -> 4.087921 | I25: =C25-E25 -> 0
A26: 7.劳务费 | B26: 13.2 | C26: 40 | D26: 21.45 | E26: 0 | F26: =D26/B26 -> 1.625 | G26: =E26/C26 -> 0 | H26: =B26-D26 -> -8.25 | I26: =C26-E26 -> 40
A27: 8.专家咨询费 | B27: 3 | C27: 0 | D27: 0.7 | E27: 0 | F27: =D27/B27 -> 0.23333333 | G27: =E27/C27 -> #DIV/0! | H27: =B27-D27 -> 2.3 | I27: =C27-E27 -> 0
A28: 9.其他支出 | B28: 0 | C28: 0 | D28: 0 | E28: 0 | F28: =D28/B28 -> #DIV/0! | G28: =E28/C28 -> #DIV/0! | H28: =B28-D28 -> 0 | I28: =C28-E28 -> 0
A29: （二）间接费用 | B29: 20 | C29: 0 | D29: 13.288 | E29: 0 | F29: =D29/B29 -> 0.6644 | G29: =E29/C29 -> #DIV/0! | H29: =B29-D29 -> 6.712 | I29: =C29-E29 -> 0
A30: 二、课题收入合计 | B30: 0 | C30: 0 | D30: 0 | E30: 0 | F30: =D30/B30 -> #DIV/0! | G30: =E30/C30 -> #DIV/0! | H30: =B30-D30 -> 0 | I30: =C30-E30 -> 0

Sheet 北航
A1: 科目 | B1: 预算批复数 | D1: 预算执行数 | F1: 执行率 | H1: 结余数
B2: 中央财政资金 | C2: 其他来源资金 | D2: 中央财政资金 | E2: 其他来源资金 | F2: 中央财政资金 | G2: 其他来源资金 | H2: 中央财政资金 | I2: 其他来源资金
A3: 一、课题支出合计 | B3: 40 | C3: 0 | D3: 9.687 | E3: 0 | F3: 0.2422 | G3: 0 | H3: 30.313 | I3: 0
A4: （一）直接费用 | B4: 40 | C4: 0 | D4: 9.687 | E4: 0 | F4: 0.2422 | G4: 0 | H4: 30.313 | I4: 0
A5: 1.设备费 | B5: 0 | C5: 0 | D5: 0 | E5: 0 | F5: 0 | G5: 0 | H5: 0 | I5: 0
A6: （1）购置设备费 | B6: 0 | C6: 0 | D6: 0 | E6: 0 | F6: 0 | G6: 0 | H6: 0 | I6: 0
A7: （2）试制设备费 | B7: 0 | C7: 0 | D7: 0 | E7: 0 | F7: 0 | G7: 0 | H7: 0 | I7: 0
A8: （3）设备改造与租赁费 | B8: 0 | C8: 0 | D8: 0 | E8: 0 | F8: 0 | G8: 0 | H8: 0 | I8: 0
A9: 1）设备改造费 | B9: 0 | C9: 0 | D9: 0 | E9: 0 | F9: 0 | G9: 0 | H9: 0 | I9: 0
A10: 2）设备租赁费 | B10: 0 | C10: 0 | D10: 0 | E10: 0 | F10: 0 | G10: 0 | H10: 0 | I10: 0
A11: 2.材料费 | B11: 23.4 | C11: 0 | D11: 2.367 | E11: 0 | F11: 0.1012 | G11: 0 | H11: 21.033 | I11: 0
A12: 3.测试化验加工费 | B12: 0.8 | C12: 0 | D12: 0.67 | E12: 0 | F12: 0.8375 | G12: 0 | H12: 0.13 | I12: 0
A13: 4.燃料动力费 | B13: 0 | C13: 0 | D13: 0 | E13: 0 | F13: 0 | G13: 0 | H13: 0 | I13: 0
A14: 5.会议/差旅/国际合作交流费 | B14: 5.4 | C14: 0 | D14: 0 | E14: 0 | F14: 0 | G14: 0 | H14: 5.4 | I14: 0
... A30: 二、课题收入合计 | B30: 0 | C30: 0 | D30: 0 | E30: 0 | F30: 0 | G30: 0 | H30: 0 | I30: 0

Sheet 中北
A1: 科目 | B1: 预算批复数 | D1: 预算执行数 | F1: 执行率 | H1: 结余数
B2: 中央财政资金 | C2: 其他来源资金 | D2: 中央财政资金 | E2: 其他来源资金 | F2: 中央财政资金 | G2: 其他来源资金 | H2: 中央财政资金 | I2: 其他来源资金
A3: 一、课题支出合计 | B3: =B4+B29 -> 80 | C3: =C4+C29 -> 160 | D3: =D4+D29 -> 22.510031 | E3: 0 | F3: =D3/B3 -> 0.28137539 | G3: 0 | H3: =B3-D3 -> 57.489969 | I3: =C3-E3 -> 160
A4: （一）直接费用 | B4: 63.7 | C4: 160 | D4: =D5+D11+D12+D13+D14+D25+D26+D27+D28 -> 17.411683 | E4: 0 | F4: =D4/B4 -> 0.27333882 | G4: 0 | H4: =B4-D4 -> 46.288317 | I4: =C4-E4 -> 160
A5: 1.设备费 | B5: 7 | C5: 10 | D5: 0 | E5: 0 | F5: =D5/B5 -> 0 | G5: 0 | H5: =B5-D5 -> 7 | I5: =C5-E5 -> 10
A6: （1）购置设备费 | B6: 7 | C6: 10 | D6: 0 | E6: 0 | F6: =D6/B6 -> 0 | G6: 0 | H6: =B6-D6 -> 7 | I6: =C6-E6 -> 10
A7: （2）试制设备费 | B7: 0 | C7: 0 | D7: 0 | E7: 0 | F7: =D7/B7 -> #DIV/0! | G7: 0 | H7: =B7-D7 -> 0 | I7: =C7-E7 -> 0
A8: （3）设备改造与租赁费 | B8: 0 | C8: 0 | D8: 0 | E8: 0 | F8: =D8/B8 -> #DIV/0! | G8: 0 | H8: =B8-D8 -> 0 | I8: =C8-E8 -> 0
A9: 1）设备改造费 | B9: 0 | C9: 0 | D9: 0 | E9: 0 | F9: =D9/B9 -> #DIV/0! | G9: 0 | H9: =B9-D9 -> 0 | I9: =C9-E9 -> 0
A10: 2）设备租赁费 | B10: 0 | C10: 0 | D10: 0 | E10: 0 | F10: =D10/B10 -> #DIV/0! | G10: 0 | H10: =B10-D10 -> 0 | I10: =C10-E10 -> 0
A11: 2.材料费 | B11: 21 | C11: 96 | D11: 9.55143 | E11: 0 | F11: =D11/B11 -> 0.45483 | G11: 0 | H11: =B11-D11 -> 11.44857 | I11: =C11-E11 -> 96
A12: 3.测试化验加工费 | B12: 5 | C12: 0 | D12: 4.9332 | E12: 0 | F12: =D12/B12 -> 0.98664 | G12: 0 | H12: =B12-D12 -> 0.0668 | I12: =C12-E12 -> 0
A13: 4.燃料动力费 | B13: 0 | C13: 0 | D13: 0 | E13: 0 | F13: =D13/B13 -> #DIV/0! | G13: 0 | H13: =B13-D13 -> 0 | I13: =C13-E13 -> 0
A14: 5.会议/差旅/国际合作交流费 | B14: 8.1 | C14: 6 | D14: 0.309553 | E14: 0 | F14: =D14/B14 -> 0.03821642 | G14: 0 | H14: =B14-D14 -> 7.790447 | I14: =C14-E14 -> 6
A25: 6.出版/文献/信息传播/知识产权事务费 | B25: 4.6 | C25: 10 | D25: 0 | E25: 0 | F25: =D25/B25 -> 0 | G25: 0 | H25: =B25-D25 -> 4.6 | I25: =C25-E25 -> 10
A26: 7.劳务费 | B26: 14 | C26: 38 | D26: 2.6175 | E26: 0 | F26: =D26/B26 -> 0.18696429 | G26: 0 | H26: =B26-D26 -> 11.3825 | I26: =C26-E26 -> 38
... A30: 二、课题收入合计 | B30: 0 | C30: 0 | D30: 0 | E30: 0 | F30: =D30/B30 -> #DIV/0! | G30: 0 | H30: =B30-D30 -> 0 | I30: =C30-E30 -> 0

Sheet 课题一
A1: 科目 | B1: 预算批复数 | D1: 预算执行数 | F1: 执行率 | H1: 结余数
B2: 中央财政资金 | C2: 其他来源资金 | D2: 中央财政资金 | E2: 其他来源资金 | F2: 中央财政资金 | G2: 其他来源资金 | H2: 中央财政资金 | I2: 其他来源资金
A3: 一、课题支出合计 | B3: =B4+B29 -> 208 | C3: =C4+C29 -> 336 | D3: =D4+D29 -> 87.117636 | E3: =SUM(浙大:中北!E3) -> 45.319165 | F3: =D3/B3 -> 0.41883479 | G3: =E3/C3 -> 0.13487847 | H3: =B3-D3 -> 120.88236 | I3: =C3-E3 -> 290.68084 | J3: =SUM(浙大:中北!D3) -> 87.117636
A4: （一）直接费用 | B4: =B5+B11+B12+B13+B14+B25+B26+B27+B28 -> 171.7 | C4: =C5+C11+C12+C13+C14+C25+C26+C27+C28 -> 336 | D4: =D5+D11+D12+D13+D14+D25+D26+D27+D28 -> 68.731288 | E4: =SUM(浙大:中北!E4) -> 45.319165 | F4: =D4/B4 -> 0.40029871 | G4: =E4/C4 -> 0.13487847 | H4: =B4-D4 -> 102.96871 | I4: =C4-E4 -> 290.68084 | J4: =SUM(浙大:中北!D4) -> 68.731288
A5: 1.设备费 | B5: 7 | C5: 10 | D5: =SUM(浙大:中北!D5) -> 0 | E5: =SUM(浙大:中北!E5) -> 0 | F5: =D5/B5 -> 0 | G5: =E5/C5 -> 0 | H5: =B5-D5 -> 7 | I5: =C5-E5 -> 10 | J5: =SUM(浙大:中北!D5) -> 0
A6: （1）购置设备费 | B6: 7 | C6: 10 | D6: =SUM(浙大:中北!D6) -> 0 | E6: =SUM(浙大:中北!E6) -> 0 | F6: =D6/B6 -> 0 | G6: =E6/C6 -> 0 | H6: =B6-D6 -> 7 | I6: =C6-E6 -> 10 | J6: =SUM(浙大:中北!D6) -> 0
A7: （2）试制设备费 | B7: 0 | C7: 0 | D7: =SUM(浙大:中北!D7) -> 0 | E7: =SUM(浙大:中北!E7) -> 0 | F7: =D7/B7 -> #DIV/0! | G7: =E7/C7 -> #DIV/0! | H7: =B7-D7 -> 0 | I7: =C7-E7 -> 0 | J7: =SUM(浙大:中北!D7) -> 0
A8: （3）设备改造与租赁费 | B8: 0 | C8: 0 | D8: =SUM(浙大:中北!D8) -> 0 | E8: =SUM(浙大:中北!E8) -> 0 | F8: =D8/B8 -> #DIV/0! | G8: =E8/C8 -> #DIV/0! | H8: =B8-D8 -> 0 | I8: =C8-E8 -> 0 | J8: =SUM(浙大:中北!D8) -> 0
A9: 1）设备改造费 | B9: 0 | C9: 0 | D9: =SUM(浙大:中北!D9) -> 0 | E9: =SUM(浙大:中北!E9) -> 0 | F9: =D9/B9 -> #DIV/0! | G9: =E9/C9 -> #DIV/0! | H9: =B9-D9 -> 0 | I9: =C9-E9 -> 0 | J9: =SUM(浙大:中北!D9) -> 0
A10: 2）设备租赁费 | B10: 0 | C10: 0 | D10: =SUM(浙大:中北!D10) -> 0 | E10: =SUM(浙大:中北!E10) -> 0 | F10: =D10/B10 -> #DIV/0! | G10: =E10/C10 -> #DIV/0! | H10: =B10-D10 -> 0 | I10: =C10-E10 -> 0 | J10: =SUM(浙大:中北!D10) -> 0
A11: 2.材料费 | B11: =SUM(浙大:中北!B11) -> 68.2 | C11: =SUM(浙大:中北!C11) -> 176 | D11: =SUM(浙大:中北!D11) -> 22.225205 | E11: =SUM(浙大:中北!E11) -> 44.6 | F11: =D11/B11 -> 0.32588277 | G11: =E11/C11 -> 0.25340909 | H11: =B11-D11 -> 45.974795 | I11: =C11-E11 -> 131.4 | J11: =SUM(浙大:中北!D11) -> 22.225205
A12: 3.测试化验加工费 | B12: =SUM(浙大:中北!B12) -> 19.8 | C12: =SUM(浙大:中北!C12) -> 56 | D12: =SUM(浙大:中北!D12) -> 5.6142 | E12: =SUM(浙大:中北!E12) -> 0 | F12: =D12/B12 -> 0.28354545 | G12: =E12/C12 -> 0 | H12: =B12-D12 -> 14.1858 | I12: =C12-E12 -> 56 | J12: =SUM(浙大:中北!D12) -> 5.6142
A13: 4.燃料动力费 | B13: =SUM(浙大:中北!B13) -> 0 | C13: =SUM(浙大:中北!C13) -> 0 | D13: =SUM(浙大:中北!D13) -> 0 | E13: =SUM(浙大:中北!E13) -> 0 | F13: =D13/B13 -> #DIV/0! | G13: =E13/C13 -> #DIV/0! | H13: =B13-D13 -> 0 | I13: =C13-E13 -> 0 | J13: =SUM(浙大:中北!D13) -> 0
A14: 5.会议/差旅/国际合作交流费 | B14: =SUM(浙大:中北!B14:B24) -> 21.5 | C14: =SUM(浙大:中北!C14:C24) -> 6 | D14: =SUM(浙大:中北!D14:D24) -> 7.562304 | E14: =SUM(浙大:中北!E14:E24) -> 0.719165 | F14: =D14/B14 -> 0.35173507 | G14: =E14/C14 -> 0.11986083 | H14: =B14-D14 -> 13.937696 | I14: =C14-E14 -> 5.280835 | J14: =SUM(浙大:中北!D14) -> 7.562304
J15: =SUM(浙大:中北!D15) -> 0
J16: =SUM(浙大:中北!D16) -> 0
J17: =SUM(浙大:中北!D17) -> 0
J18: =SUM(浙大:中北!D18) -> 0
J19: =SUM(浙大:中北!D19) -> 0
J20: =SUM(浙大:中北!D20) -> 0
J21: =SUM(浙大:中北!D21) -> 0
J22: =SUM(浙大:中北!D22) -> 0
J23: =SUM(浙大:中北!D23) -> 0
J24: =SUM(浙大:中北!D24) -> 0
A25: 6.出版/文献/信息传播/知识产权事务费 | B25: =SUM(浙大:中北!B25) -> 14 | C25: =SUM(浙大:中北!C25) -> 10 | D25: =SUM(浙大:中北!D25) -> 5.622079 | E25: =SUM(浙大:中北!E25) -> 0 | F25: =D25/B25 -> 0.40157707 | G25: =E25/C25 -> 0 | H25: =B25-D25 -> 8.377921 | I25: =C25-E25 -> 10 | J25: =SUM(浙大:中北!D25) -> 5.622079
A26: 7.劳务费 | B26: =SUM(浙大:中北!B26) -> 33.2 | C26: =SUM(浙大:中北!C26) -> 78 | D26: =SUM(浙大:中北!D26) -> 27.0075 | E26: =SUM(浙大:中北!E26) -> 0 | F26: =D26/B26 -> 0.81347892 | G26: =E26/C26 -> 0 | H26: =B26-D26 -> 6.1925 | I26: =C26-E26 -> 78 | J26: =SUM(浙大:中北!D26) -> 27.0075
A27: 8.专家咨询费 | B27: =SUM(浙大:中北!B27) -> 8 | C27: =SUM(浙大:中北!C27) -> 0 | D27: =SUM(浙大:中北!D27) -> 0.7 | E27: =SUM(浙大:中北!E27) -> 0 | F27: =D27/B27 -> 0.0875 | G27: =E27/C27 -> #DIV/0! | H27: =B27-D27 -> 7.3 | I27: =C27-E27 -> 0 | J27: =SUM(浙大:中北!D27) -> 0.7
A28: 9.其他支出 | B28: =SUM(浙大:中北!B28) -> 0 | C28: =SUM(浙大:中北!C28) -> 0 | D28: =SUM(浙大:中北!D28) -> 0 | E28: =SUM(浙大:中北!E28) -> 0 | F28: =D28/B28 -> #DIV/0! | G28: =E28/C28 -> #DIV/0! | H28: =B28-D28 -> 0 | I28: =C28-E28 -> 0 | J28: =SUM(浙大:中北!D28) -> 0
A29: （二）间接费用 | B29: =SUM(浙大:中北!B29) -> 36.3 | C29: =SUM(浙大:中北!C29) -> 0 | D29: =SUM(浙大:中北!D29) -> 18.386348 | E29: =SUM(浙大:中北!E29) -> 0 | F29: =D29/B29 -> 0.50651096 | G29: =E29/C29 -> #DIV/0! | H29: =B29-D29 -> 17.913652 | I29: =C29-E29 -> 0 | J29: =SUM(浙大:中北!D29) -> 18.386348
A30: 二、课题收入合计 | B30: =SUM(浙大:中北!B30) -> 0 | C30: =SUM(浙大:中北!C30) -> 0 | D30: =SUM(浙大:中北!D30) -> 0 | E30: =SUM(浙大:中北!E30) -> 0 | F30: =D30/B30 -> #DIV/0! | G30: =E30/C30 -> #DIV/0! | H30: =B30-D30 -> 0 | I30: =C30-E30 -> 0 | J30: =SUM(浙大:中北!D30) -> 0
A36: 总资金 | C36: 中央财政专项资金 | J36: 其他来源资金
A37: 预算数 | B37: 累计到位数 | C37: 预算数 | E37: 累计到位数 | G37: 拨付课题参与单位金额 | H37: 累计资金支出数 | I37: 是否按计划拨付课题参与单位 | J37: 预算数 | K37: 累计到位数 | L37: 累计资金支出数
A38: 544 | B38: 149.76 | C38: 208 | E38: 149.76 | G38: 86.4 | H38: 87.12 | I38: 是 | J38: 336 | K38: 336 | L38: 45.32
A39: 总人数 | B39: 其中女性 | C39: 高级职称 | D39: 中级职称 | E39: 初职职称 | F39: 其他人员 | G39: 博士 | H39: 硕士 | I39: 学士 | J39: 其他学历 | K39: 总人年
A40: 28 | B40: 7 | C40: 2 | D40: 0 | E40: 0 | F40: 8 | G40: 21 | H40: 2 | I40: 5 | J40: 0 | K40: 25
A50: 序号 | B50: 栏目 | D50: 资金来源合计 | E50: 中央财政资金 | F50: 其他来源资金
F51: 小计 | G51: （1）地方财政资金 | H51: （2）单位自有资金 | I51: （3）其他资金
A52: 1 | B52: 预算批复数 | D52: 544 | E52: 208 | F52: 336
A53: 2 | B53: 累计到位数 | D53: 149.76 | E53: 149.76 | F53: 336
A54: -1 | B54: 2025年 | C54: 当年到位数 | D54: 149.76 | E54: 149.76 | F54: 336
...

Sheet 课题二
A1: 科目 | B1: 预算批复数 | D1: 预算执行数 | F1: 执行率 | H1: 结余数
B2: 中央财政资金 | C2: 其他来源资金 | D2: 中央财政资金 | E2: 其他来源资金 | F2: 中央财政资金 | G2: 其他来源资金 | H2: 中央财政资金 | I2: 其他来源资金
A3: 一、课题支出合计 | B3: 152 | C3: 224 | D3: 61.3 | E3: 18.1 | F3: 0.4033 | G3: =E3/C3 -> 0.080803571 | H3: 90.7 | I3: 205.9
A4: （一）直接费用 | B4: 125.8 | C4: 224 | D4: 49.06 | E4: 18.1 | F4: 0.39 | G4: =E4/C4 -> 0.080803571 | H4: 76.74 | I4: 205.9
A5: 1.设备费 | B5: 0 | C5: 0 | D5: 0 | E5: 0 | F5: 0 | G5: 0 | H5: 0 | I5: 0
A6: （1）购置设备费
A7: （2）试制设备费
A8: （3）设备改造与租赁费
A9: 1）设备改造费
A10: 2）设备租赁费
A11: 2.材料费 | B11: 50 | C11: 99 | D11: 6.77 | E11: 0 | F11: 0.1354 | G11: 0 | H11: 43.23 | I11: 99
A12: 3.测试化验加工费 | B12: 37.2 | C12: 92.5 | D12: 27.8 | E12: 0 | F12: 0.7473 | G12: 0 | H12: 9.4 | I12: 92.5
A13: 4.燃料动力费 | B13: 0 | C13: 11.5 | D13: 0 | E13: 0 | G13: 0 | I13: 11.5
A14: 5.会议/差旅/国际合作交流费 | B14: 7.9 | C14: 0 | D14: 3.76 | E14: 0 | F14: 0.3798 | G14: 0 | H14: 4.14 | I14: 0
A25: 6.出版/文献/信息传播/知识产权事务费 | B25: 6.6 | C25: 0 | D25: 0 | E25: 0 | G25: 0 | H25: 6.6 | I25: 0
A26: 7.劳务费 | B26: 20.1 | C26: 21 | D26: 10.73 | E26: 18.1 | F26: 0.5338 | G26: =E26/C26 -> 0.86190476 | H26: 9.37 | I26: 2.9
A27: 8.专家咨询费 | B27: 2 | C27: 0 | D27: 0 | E27: 0 | G27: 0 | H27: 2 | I27: 0
A28: 9.其他支出 | B28: 0 | C28: 0 | D28: 0 | E28: 0 | I28: 0
A29: （二）间接费用 | B29: 26.2 | C29: 0 | D29: 12.24 | E29: 0 | F29: 0.4672 | H29: 13.96 | I29: 0
A30: 二、课题收入合计
A36: 总资金 | C36: 中央财政专项资金 | J36: 其他来源资金
A37: 预算数 | B37: 累计到位数 | C37: 预算数 | E37: 累计到位数 | G37: 拨付课题参与单位金额 | H37: 累计资金支出数 | I37: 是否按计划拨付课题参与单位 | J37: 预算数 | K37: 累计到位数 | L37: 累计资金支出数
A38: 376 | B38: 127.54 | C38: 152 | E38: 109.44 | G38: 28.8 | H38: 90.7 | I38: 是 | J38: 224 | K38: 18.1 | L38: 18.1
A39: 总人数 | B39: 其中女性 | C39: 高级职称 | D39: 中级职称 | E39: 初职职称 | F39: 其他人员 | G39: 博士 | H39: 硕士 | I39: 学士 | J39: 其他学历 | K39: 总人年
A40: 15 | B40: 1 | C40: 3 | D40: 0 | E40: 0 | F40: 12 | G40: 3 | H40: 12 | I40: 0 | J40: 0 | K40: 5
A50: 序号 | B50: 栏目 | D50: 资金来源合计 | E50: 中央财政资金 | F50: 其他来源资金
F51: 小计 | G51: （1）地方财政资金 | H51: （2）单位自有资金 | I51: （3）其他资金
A52: 1 | B52: 预算批复数 | D52: 376 | E52: 152 | F52: 376
A53: 2 | B53: 累计到位数 | D53: 109.44 | E53: 109.44 | F53: 109.44
A54: -1 | B54: 2025年 | C54: 当年到位数 | D54: 109.44 | E54: 109.44 | F54: 109.44
C55: 资金到款时间（以银行入账时间为准） | D55: - | E55: 2025.6.18 | F55: -
A56: -2 | B56: 2026年 | C56: 当年到位数 | D56: 0 | E56: 0 | F56: 0
C57: 资金到款时间（以银行入账时间为准） | D57: - | E57: - | F57: -

Sheet 课题三
A1: 科目 | B1: 预算批复数 | D1: 预算执行数 | F1: 执行率 | H1: 结余数
B2: 中央财政资金 | C2: 其他来源资金 | D2: 中央财政资金 | E2: 其他来源资金 | F2: 中央财政资金 | G2: 其他来源资金 | H2: 中央财政资金 | I2: 其他来源资金
A3: 一、课题支出合计 | B3: 152 | C3: 0 | D3: 86.07 | E3: 0 | F3: 0.5663 | G3: 0 | H3: 65.93 | I3: 0
A4: （一）直接费用 | B4: 119 | C4: 0 | D4: 64.07 | E4: 0 | F4: 0.5384 | G4: 0 | H4: 54.93 | I4: 0
A5: 1.设备费 | B5: 0 | C5: 0 | D5: 0 | E5: 0 | F5: 0 | G5: 0 | H5: 0 | I5: 0
A6: （1）购置设备费 | B6: 0 | C6: 0 | D6: 0 | E6: 0 | F6: 0 | G6: 0 | H6: 0 | I6: 0
A7: （2）试制设备费 | B7: 0 | C7: 0 | D7: 0 | E7: 0 | F7: 0 | G7: 0 | H7: 0 | I7: 0
A8: （3）设备改造与租赁费 | B8: 0 | C8: 0 | D8: 0 | E8: 0 | F8: 0 | G8: 0 | H8: 0 | I8: 0
A9: 1）设备改造费 | B9: 0 | C9: 0 | D9: 0 | E9: 0 | F9: 0 | G9: 0 | H9: 0 | I9: 0
A10: 2）设备租赁费 | B10: 0 | C10: 0 | D10: 0 | E10: 0 | F10: 0 | G10: 0 | H10: 0 | I10: 0
A11: 2.材料费 | B11: 28.2 | C11: 0 | D11: 11.7 | E11: 0 | F11: 0.4149 | G11: 0 | H11: 16.5 | I11: 0
A12: 3.测试化验加工费 | B12: 47.5 | C12: 0 | D12: 28.18 | E12: 0 | F12: 0.5933 | G12: 0 | H12: 19.32 | I12: 0
A13: 4.燃料动力费 | B13: 0 | C13: 0 | D13: 0 | E13: 0 | F13: 0 | G13: 0 | H13: 0 | I13: 0
A14: 5.会议/差旅/国际合作交流费 | B14: 8.2 | C14: 0 | D14: 8.32 | E14: 0 | F14: 1.0146 | G14: 0 | H14: -0.12 | I14: 0
... A28: 9.其他支出 | B28: 0 | C28: 0 | D28: 0 | E28: 0 | F28: 0 | G28: 0 | H28: 0 | I28: 0
A36: 总资金 | C36: 中央财政专项资金 | J36: 其他来源资金
A37: 预算数 | B37: 累计到位数 | C37: 预算数 | E37: 累计到位数 | G37: 拨付课题参与单位金额 | H37: 累计资金支出数 | I37: 是否按计划拨付课题参与单位 | J37: 预算数 | K37: 累计到位数 | L37: 累计资金支出数
A38: 152 | B38: 109.44 | C38: 152 | E38: 109.44 | G38: 28.8 | H38: 86.07 | I38: 是 | J38: 0 | K38: 0 | L38: 0
A39: 总人数 | B39: 其中女性 | C39: 高级职称 | D39: 中级职称 | E39: 初职职称 | F39: 其他人员 | G39: 博士 | H39: 硕士 | I39: 学士 | J39: 其他学历 | K39: 总人年
A40: 15 | B40: 3 | C40: 3 | D40: 0 | E40: 0 | F40: 0 | G40: 5 | H40: 3 | I40: 7 | J40: 0 | K40: 27.25
A50: 序号 | B50: 栏目 | D50: 资金来源合计 | E50: 中央财政资金 | F50: 其他来源资金
F51: 小计 | G51: （1）地方财政资金 | H51: （2）单位自有资金 | I51: （3）其他资金
A52: 1 | B52: 预算批复数 | D52: 152 | E52: 152 | F52: 152
A53: 2 | B53: 累计到位数 | D53: 109.44 | E53: 109.44 | F53: 109.44
A54: -1 | B54: 2025年 | C54: 当年到位数 | D54: 109.44 | E54: 109.44 | F54: 109.44
C55: 资金到款时间（以银行入账时间为准） | D55: 45835 | E55: 45835 | F55: -
A56: -2 | B56: 2026年 | C56: 当年到位数 | D56: 0 | E56: 0 | F56: 0
C57: 资金到款时间（以银行入账时间为准） | D57: - | E57: - | F57: -

Sheet 课题四
A36: 总资金 | C36: 中央财政专项资金 | J36: 其他来源资金
A37: 预算数 | B37: 累计到位数 | C37: 预算数 | E37: 累计到位数 | G37: 拨付课题参与单位金额 | H37: 累计资金支出数 | I37: 是否按计划拨付课题参与单位 | J37: 预算数 | K37: 累计到位数 | L37: 累计资金支出数
A38: 400 | B38: 318 | C38: 135 | E38: 126 | G38: 40 | H38: 115.77 | I38: 是 | J38: 265 | K38: 192 | L38: 60.58
A39: 总人数 | B39: 其中女性 | C39: 高级职称 | D39: 中级职称 | E39: 初职职称 | F39: 其他人员 | G39: 博士 | H39: 硕士 | I39: 学士 | J39: 其他学历 | K39: 总人年
A40: 20 | B40: 5 | C40: 16 | D40: 2 | E40: 0 | F40: 2 | G40: 11 | H40: 7 | I40: 2 | J40: 0 | K40: 15

Sheet 课题五

Sheet 项目合计
A1: 科目 | B1: 预算批复数 | D1: 预算执行数 | F1: 执行率 | H1: 结余数
B2: 中央财政资金 | C2: 其他来源资金 | D2: 中央财政资金 | E2: 其他来源资金 | F2: 中央财政资金 | G2: 其他来源资金 | H2: 中央财政资金 | I2: 其他来源资金
A3: 一、课题支出合计 | B3: =SUM(课题一:课题五!B3) -> 512 | C3: =SUM(课题一:课题五!C3) -> 560 | D3: =SUM(课题一:课题五!D3) -> 234.48764 | E3: =SUM(课题一:课题五!E3) -> 63.419165 | F3: =D3/B3 -> 0.45798366 | G3: =E3/C3 -> 0.11324851 | H3: =B3-D3 -> 277.51236 | I3: =C3-E3 -> 496.58083 | J3: =SUM(课题一:课题五!H3) -> 277.51236 | K3: =SUM(课题一:课题五!I3) -> 496.58083
A4: （一）直接费用 | B4: =SUM(课题一:课题五!B4) -> 416.5 | C4: =SUM(课题一:课题五!C4) -> 560 | D4: =SUM(课题一:课题五!D4) -> 181.86129 | E4: =SUM(课题一:课题五!E4) -> 63.419165 | F4: =D4/B4 -> 0.43664175 | G4: =E4/C4 -> 0.11324851 | H4: =B4-D4 -> 234.63871 | I4: =C4-E4 -> 496.58083 | J4: =SUM(课题一:课题五!H4) -> 234.63871 | K4: =SUM(课题一:课题五!I4) -> 496.58083
A5: 1.设备费 | B5: =SUM(课题一:课题五!B5) -> 7 | C5: =SUM(课题一:课题五!C5) -> 10 | D5: =SUM(课题一:课题五!D5) -> 0 | E5: =SUM(课题一:课题五!E5) -> 0 | F5: =D5/B5 -> 0 | G5: =E5/C5 -> 0 | H5: =B5-D5 -> 7 | I5: =C5-E5 -> 10 | J5: =SUM(课题一:课题五!H5) -> 7 | K5: =SUM(课题一:课题五!I5) -> 10
A6: （1）购置设备费 | B6: =SUM(课题一:课题五!B6) -> 7 | C6: =SUM(课题一:课题五!C6) -> 10 | D6: =SUM(课题一:课题五!D6) -> 0 | E6: =SUM(课题一:课题五!E6) -> 0 | F6: =D6/B6 -> 0 | G6: =E6/C6 -> 0 | H6: =B6-D6 -> 7 | I6: =C6-E6 -> 10 | J6: =SUM(课题一:课题五!H6) -> 7 | K6: =SUM(课题一:课题五!I6) -> 10
A7: （2）试制设备费 | B7: =SUM(课题一:课题五!B7) -> 0 | C7: =SUM(课题一:课题五!C7) -> 0 | D7: =SUM(课题一:课题五!D7) -> 0 | E7: =SUM(课题一:课题五!E7) -> 0 | F7: 0 | G7: =E7/C7 -> #DIV/0! | H7: =B7-D7 -> 0 | I7: =C7-E7 -> 0 | J7: =SUM(课题一:课题五!H7) -> 0 | K7: =SUM(课题一:课题五!I7) -> 0
A8: （3）设备改造与租赁费 | B8: =SUM(课题一:课题五!B8) -> 0 | C8: =SUM(课题一:课题五!C8) -> 0 | D8: =SUM(课题一:课题五!D8) -> 0 | E8: =SUM(课题一:课题五!E8) -> 0 | F8: 0 | G8: =E8/C8 -> #DIV/0! | H8: =B8-D8 -> 0 | I8: =C8-E8 -> 0 | J8: =SUM(课题一:课题五!H8) -> 0 | K8: =SUM(课题一:课题五!I8) -> 0
A9: 1）设备改造费 | B9: =SUM(课题一:课题五!B9) -> 0 | C9: =SUM(课题一:课题五!C9) -> 0 | D9: =SUM(课题一:课题五!D9) -> 0 | E9: =SUM(课题一:课题五!E9) -> 0 | F9: 0 | G9: =E9/C9 -> #DIV/0! | H9: =B9-D9 -> 0 | I9: =C9-E9 -> 0 | J9: =SUM(课题一:课题五!H9) -> 0 | K9: =SUM(课题一:课题五!I9) -> 0
A10: 2）设备租赁费 | B10: =SUM(课题一:课题五!B10) -> 0 | C10: =SUM(课题一:课题五!C10) -> 0 | D10: =SUM(课题一:课题五!D10) -> 0 | E10: =SUM(课题一:课题五!E10) -> 0 | F10: 0 | G10: =E10/C10 -> #DIV/0! | H10: =B10-D10 -> 0 | I10: =C10-E10 -> 0 | J10: =SUM(课题一:课题五!H10) -> 0 | K10: =SUM(课题一:课题五!I10) -> 0
A11: 2.材料费 | B11: =SUM(课题一:课题五!B11) -> 146.4 | C11: =SUM(课题一:课题五!C11) -> 275 | D11: =SUM(课题一:课题五!D11) -> 40.695205 | E11: =SUM(课题一:课题五!E11) -> 44.6 | F11: =D11/B11 -> 0.27797271 | G11: =E11/C11 -> 0.16218182 | H11: =B11-D11 -> 105.7048 | I11: =C11-E11 -> 230.4 | J11: =SUM(课题一:课题五!H11) -> 105.70479 | K11: =SUM(课题一:课题五!I11) -> 230.4
A12: 3.测试化验加工费 | B12: =SUM(课题一:课题五!B12) -> 104.5 | C12: =SUM(课题一:课题五!C12) -> 148.5 | D12: =SUM(课题一:课题五!D12) -> 61.5942 | E12: =SUM(课题一:课题五!E12) -> 0 | F12: =D12/B12 -> 0.58941818 | G12: =E12/C12 -> 0 | H12: =B12-D12 -> 42.9058 | I12: =C12-E12 -> 148.5 | J12: =SUM(课题一:课题五!H12) -> 42.9058 | K12: =SUM(课题一:课题五!I12) -> 148.5
A13: 4.燃料动力费 | B13: =SUM(课题一:课题五!B13) -> 0 | C13: =SUM(课题一:课题五!C13) -> 11.5 | D13: =SUM(课题一:课题五!D13) -> 0 | E13: =SUM(课题一:课题五!E13) -> 0 | F13: 0 | G13: =E13/C13 -> 0 | H13: =B13-D13 -> 0 | I13: =C13-E13 -> 11.5 | J13: =SUM(课题一:课题五!H13) -> 0 | K13: =SUM(课题一:课题五!I13) -> 11.5
A14: 5.会议/差旅/国际合作交流费 | B14: =SUM(课题一:课题五!B14:B24) -> 37.6 | C14: =SUM(课题一:课题五!C14:C24) -> 6 | D14: =SUM(课题一:课题五!D14:D24) -> 19.642304 | E14: =SUM(课题一:课题五!E14:E24) -> 0.719165 | F14: =D14/B14 -> 0.5224017 | G14: =E14/C14 -> 0.11986083 | H14: =B14-D14 -> 17.957696 | I14: =C14-E14 -> 5.280835 | J14: =SUM(课题一:课题五!H14:H24) -> 17.957696 | K14: =SUM(课题一:课题五!I14:I24) -> 5.280835
A25: 6.出版/文献/信息传播/知识产权事务费 | B25: =SUM(课题一:课题五!B25) -> 23.6 | C25: =SUM(课题一:课题五!C25) -> 10 | D25: =SUM(课题一:课题五!D25) -> 6.972079 | E25: =SUM(课题一:课题五!E25) -> 0 | F25: =D25/B25 -> 0.29542708 | G25: =E25/C25 -> 0 | H25: =B25-D25 -> 16.627921 | I25: =C25-E25 -> 10 | J25: =SUM(课题一:课题五!H25) -> 16.627921 | K25: =SUM(课题一:课题五!I25) -> 10
A26: 7.劳务费 | B26: =SUM(课题一:课题五!B26) -> 83.9 | C26: =SUM(课题一:课题五!C26) -> 99 | D26: =SUM(课题一:课题五!D26) -> 51.9575 | E26: =SUM(课题一:课题五!E26) -> 18.1 | F26: =D26/B26 -> 0.6192789 | G26: =E26/C26 -> 0.18282828 | H26: =B26-D26 -> 31.9425 | I26: =C26-E26 -> 80.9 | J26: =SUM(课题一:课题五!H26) -> 31.9425 | K26: =SUM(课题一:课题五!I26) -> 80.9
A27: 8.专家咨询费 | B27: =SUM(课题一:课题五!B27) -> 11.5 | C27: =SUM(课题一:课题五!C27) -> 0 | D27: =SUM(课题一:课题五!D27) -> 1 | E27: =SUM(课题一:课题五!E27) -> 0 | F27: =D27/B27 -> 0.086956522 | G27: =E27/C27 -> #DIV/0! | H27: =B27-D27 -> 10.5 | I27: =C27-E27 -> 0 | J27: =SUM(课题一:课题五!H27) -> 10.5 | K27: =SUM(课题一:课题五!I27) -> 0
A28: 9.其他支出 | B28: =SUM(课题一:课题五!B28) -> 0 | C28: =SUM(课题一:课题五!C28) -> 0 | D28: =SUM(课题一:课题五!D28) -> 0 | E28: =SUM(课题一:课题五!E28) -> 0 | F28: 0 | G28: =E28/C28 -> #DIV/0! | H28: =B28-D28 -> 0 | I28: =C28-E28 -> 0 | J28: =SUM(课题一:课题五!H28) -> 0 | K28: =SUM(课题一:课题五!I28) -> 0
A29: （二）间接费用 | B29: =SUM(课题一:课题五!B29) -> 62.5 | C29: =SUM(课题一:课题五!C29) -> 0 | D29: =SUM(课题一:课题五!D29) -> 30.626348 | E29: =SUM(课题一:课题五!E29) -> 0 | F29: =D29/B29 -> 0.49002157 | G29: =E29/C29 -> #DIV/0! | H29: =B29-D29 -> 31.873652 | I29: =C29-E29 -> 0 | J29: =SUM(课题一:课题五!H29) -> 31.873652 | K29: =SUM(课题一:课题五!I29) -> 0
A30: 二、课题收入合计 | B30: =SUM(课题一:课题五!B30) -> 0 | C30: =SUM(课题一:课题五!C30) -> 0 | D30: =SUM(课题一:课题五!D30) -> 0 | E30: =SUM(课题一:课题五!E30) -> 0 | F30: 0 | G30: =E30/C30 -> #DIV/0! | H30: =B30-D30 -> 0 | I30: =C30-E30 -> 0 | J30: =SUM(课题一:课题五!H30) -> 0 | K30: =SUM(课题一:课题五!I30) -> 0
A36: 总资金 | C36: 中央财政专项资金 | J36: 其他来源资金
A37: 预算数 | B37: 累计到位数 | C37: 预算数 | E37: 累计到位数 | G37: 拨付课题参与单位金额 | H37: 累计资金支出数 | I37: 是否按计划拨付课题参与单位 | J37: 预算数 | K37: 累计到位数 | L37: 累计资金支出数
A38: =SUM(课题一:课题五!A38) -> 1472 | B38: =SUM(课题一:课题五!B38) -> 704.74 | C38: =SUM(课题一:课题五!C38:D38) -> 647 | E38: =SUM(课题一:课题五!E38:F38) -> 494.64 | G38: =SUM(课题一:课题五!G38) -> 184 | H38: =SUM(课题一:课题五!H38) -> 379.66 | I38: 是 | J38: =SUM(课题一:课题五!J38) -> 825 | K38: =SUM(课题一:课题五!K38) -> 546.1 | L38: =SUM(课题一:课题五!L38) -> 124
A39: 总人数 | B39: 其中女性 | C39: 高级职称 | D39: 中级职称 | E39: 初职职称 | F39: 其他人员 | G39: 博士 | H39: 硕士 | I39: 学士 | J39: 其他学历 | K39: 总人年
A40: =SUM(课题一:课题五!A40) -> 78 | B40: =SUM(课题一:课题五!B40) -> 16 | C40: =SUM(课题一:课题五!C40) -> 24 | D40: =SUM(课题一:课题五!D40) -> 2 | E40: =SUM(课题一:课题五!E40) -> 0 | F40: =SUM(课题一:课题五!F40) -> 22 | G40: =SUM(课题一:课题五!G40) -> 40 | H40: =SUM(课题一:课题五!H40) -> 24 | ... J40: =SUM(课题一:课题五!J40) -> 0 | K40: =SUM(课题一:课题五!K40:L40) -> 72.25
A50: 序号 | B50: 栏目 | D50: 资金来源合计 | E50: 中央财政资金 | F50: 其他来源资金
F51: 小计 | G51: （1）地方财政资金 | H51: （2）单位自有资金 | I51: （3）其他资金
A52: 1 | B52: 预算批复数 | D52: =SUM(课题一:课题五!D52) -> 1072 | E52: =SUM(课题一:课题五!E52) -> 512 | F52: =SUM(课题一:课题五!F52) -> 864 | G52: =SUM(课题一:课题五!G52) -> 0 | H52: =SUM(课题一:课题五!H52) -> 0 | I52: =SUM(课题一:课题五!I52) -> 0
A53: 2 | B53: 累计到位数 | D53: =SUM(课题一:课题五!D53) -> 368.64 | E53: =SUM(课题一:课题五!E53) -> 368.64 | F53: =SUM(课题一:课题五!F53) -> 554.88 | G53: =SUM(课题一:课题五!G53) -> 0 | H53: =SUM(课题一:课题五!H53) -> 0 | I53: =SUM(课题一:课题五!I53) -> 0
A54: -1 | B54: 2025年 | C54: 当年到位数 | D54: =SUM(课题一:课题五!D54) -> 368.64 | E54: =SUM(课题一:课题五!E54) -> 368.64 | F54: =SUM(课题一:课题五!F54) -> 554.88 | G54: =SUM(课题一:课题五!G54) -> 0 | H54: =SUM(课题一:课题五!H54) -> 0 | I54: =SUM(课题一:课题五!I54) -> 0
C55: 资金到款时间（以银行入账时间为准） | D55: 45835 | E55: 45835 | F55: -
A56: -2 | B56: 2026年 | C56: 当年到位数 | D56: 0 | E56: 0 | F56: 0
C57: 资金到款时间（以银行入账时间为准） | D57: - | E57: - | F57: -
